Workbook

Sheet Vol1_LOCK
A1: 正典ID | B1: gate_pass | C1: 篇名（中） | D1: 三原理三元组 | E1: carrier | F1: status
A2: A001 | B2: G1–G7 Y | C2: 翘边的海报 | D2: 侧廊出风 + 晨间湿度 + 胶带黏着 | E2: 校园 | F2: 样章+正文✅
A3: A002 | B3: G1–G7 Y | C3: 错位的泥印 | D3: 鞋柜动线 + 目击链 + 泥印方向 | E3: 校园 | F3: 正文✅
A4: A003 | B4: G1–G7 Y | C4: 空着的那一栏 | D4: 核实流程 + 采访伦理 + 无源收束 | E4: 校园 | F4: 正文✅
A5: A004 | B5: G1–G7 Y | C5: 粉笔灰的圆圈 | D5: 静电吸附 + 粉笔粉尘 + 清扫动线 | E5: 校园 | F5: Card✅
A6: A005 | B6: G1–G7 Y | C6: 橡皮屑的方向 | D6: 摩擦痕迹 + 振动滑出 + 行为链 | E6: 校园 | F6: Card✅

Sheet 前100篇台账
A1: 正典ID | B1: gate_pass | C1: 案号 | D1: 篇名（日） | E1: 篇名（中） | F1: 阶段 | G1: 层级 | H1: 载体 | I1: 季节 | J1: 领衔 | K1: 参与全员 | L1: 知识域 1 | M1: 知识域 2 | N1: 知识域 3 | O1: 三原理三元组（标准化） | P1: 主范式 | Q1: 长线标记 | R1: 重复校验
A2: A001 | B2: ポスターの端 | C2: 翘边的海报 | D2: I 组建期 | E2: 核心连载 | F2: 校园 | G2: 4月 | H2: 慧美·志郎·光 | I2: 光·慧美·志郎·珣（+瑆 笔记） | J2: 气象 | K2: 材料 | L2: 流体 | M2: 侧廊出风 + 晨间湿度 + 胶带黏着 | N2: 实验+观察 | O2: Vol1·样章 | P2: G1–G7 Y
A3: A002 | B3: ずれた泥の跡 | C3: 错位的泥印 | D3: I 组建期 | E3: 核心连载 | F3: 校园 | G3: 4月 | H3: 慧美·光 | I3: 光·慧美·志郎·珣（+瑆 笔记） | J3: 行为 | K3: 动线 | L3: 地理 | M3: 鞋柜动线 + 目击链 + 泥印方向 | N3: 采访+实验 | P3: G1–G7 Y
A4: A003 | B4: 空いた欄 | C4: 空着的那一栏 | D4: I 组建期 | E4: 核心连载 | F4: 校园 | G4: 4月 | H4: 慧美 | I4: 光·慧美·志郎·珣（+瑆 笔记） | J4: 逻辑 | K4: 心理 | L4: 传播 | M4: 核实流程 + 采访伦理 + 无源收束 | N4: 采访+逻辑 | P4: G1–G7 Y
A5: A004 | B5: チョークの円 | C5: 粉笔灰的圆圈 | D5: I 组建期 | E5: 核心连载 | F5: 校园 | G5: 4月 | H5: 志郎·珣 | I5: 光·慧美·志郎·珣（+瑆 笔记） | J5: 静电 | K5: 材料 | L5: 行为 | M5: 静电吸附 + 粉笔粉尘 + 清扫动线 | N5: 实验+结构 | P5: G1–G7 Y
A6: A005 | B6: 消しゴムの屑 | C6: 橡皮屑的方向 | D6: I 组建期 | E6: 核心连载 | F6: 校园 | G6: 4月 | H6: 志郎·珣 | I6: 光·慧美·志郎·珣（+瑆 笔记） | J6: 力学 | K6: 材料 | L6: 行为 | M6: 摩擦痕迹 + 振动滑出 + 行为链 | N6: 结构还原 | O6: 珣入社 | P6: G1–G7 Y
A7: C001 | B7: G1=N · 素材库 | C7: 1 | D7: 濡れる椅子 | E7: 总是湿的椅子 | F7: I 组建期 | G7: 核心连载 | H7: 校园 | I7: 4月 | J7: 光·慧美·珣 | K7: 光·慧美·志郎·珣（+瑆 笔记） | L7: 热学 | M7: 热传导 | N7: 气象 | O7: 窗框热传导 + 结露 + 露点湿度 | P7: 实验+微观 | Q7: C001·热学深潜（非入社） | R7: =IF(COUNTIF($M$2:$M$101,M2)>1,"⚠ 重复","唯一")
A8: A006 | B8: ⬜ | C8: 2 | D8: 転がる消しゴム | E8: 谁偷了橡皮 | F8: I 组建期 | G8: 核心连载 | H8: 校园 | I8: 5月 | J8: 志郎 | K8: 光·慧美·志郎·珣（+瑆 笔记） | L8: 力学 | M8: 材料 | N8: 行为 | O8: 摩擦力 + 斜面滚动 + 行为习惯 | P8: 结构还原 | R8: =IF(COUNTIF($M$2:$M$101,M3)>1,"⚠ 重复","唯一")
A9: A007 | B9: ⬜ | C9: 3 | D9: アリの行列 | E9: 蚂蚁的队列 | F9: I 组建期 | G9: 核心连载 | H9: 校园·操场 | I9: 6月梅雨 | J9: 珣 | K9: 光·慧美·志郎·珣（+瑆 笔记） | L9: 生物 | M9: 化学 | N9: 气象 | O9: 信息素挥发 + 昆虫信息素 + 湿度扩散 | P9: 微观领域 | R9: =IF(COUNTIF($M$2:$M$101,M4)>1,"⚠ 重复","唯一")
A10: A008 | B10: ⬜ | C10: 4 | D10: 音楽室の和音 | E10: 音乐教室的怪声 | F10: I 组建期 | G10: 核心连载 | H10: 校园 | I10: 7月 | J10: 珣 | K10: 光·慧美·志郎·珣（+瑆 笔记） | L10: 声学 | M10: 音乐 | N10: 材料 | O10: 共振 + 和弦泛音 + 固体传声 | P10: 微观 | R10: =IF(COUNTIF($M$2:$M$101,M5)>1,"⚠ 重复","唯一")
A11: A009 | B11: ⬜ | C11: 5 | D11: 旗竿の影 | E11: 歪掉的旗杆影子 | F11: I 组建期 | G11: 核心连载 | H11: 校园·操场 | I11: 10月运动会 | J11: 慧美·珣 | K11: 光·慧美·志郎·珣（+瑆 笔记） | L11: 天文 | M11: 地理 | N11: 数学 | O11: 几何投影 + 太阳高度角 + 纬度时差 | P11: 实验+结构 | R11: =IF(COUNTIF($M$2:$M$101,M6)>1,"⚠ 重复","唯一")
A12: A010 | B12: ⬜ | C12: 6 | D12: 蛇口のぬるま湯 | E12: 水龙头里的温水 | F12: I 组建期 | G12: 核心连载 | H12: 校园 | I12: 8月 | J12: 志郎 | K12: 光·慧美·志郎·珣（+瑆 笔记） | L12: 热学 | M12: 地质 | N12: 工程 | O12: 土壤比热 + 管道埋深 + 管道热传导 | P12: 结构还原 | R12: =IF(COUNTIF($M$2:$M$101,M7)>1,"⚠ 重复","唯一")
A13: A011 | B13: ⬜ | C13: 7 | D13: 植木鉢の白い骨 | E13: 花盆里的白骨 | F13: I 组建期 | G13: 核心连载 | H13: 校园·植物角 | I13: 11月 | J13: 珣 | K13: 光·慧美·志郎·珣（+瑆 笔记） | L13: 微生物 | M13: 植物 | N13: 化学 | O13: 共生关系 + 真菌菌丝 + 菌丝代谢 | P13: 微观 | R13: =IF(COUNTIF($M$2:$M$101,M8)>1,"⚠ 重复","唯一")
A14: A012 | B14: ⬜ | C14: 8 | D14: 遅れる時計 | E14: 不走的钟 | F14: I 组建期 | G14: 核心连载 | H14: 校园 | I14: 12月 | J14: 慧美·珣 | K14: 光·慧美·志郎·珣（+瑆 笔记） | L14: 电子 | M14: 热学 | N14: 数学 | O14: 温差 + 石英晶振温度特性 + 误差累积 | P14: 实验+微观 | R14: =IF(COUNTIF($M$2:$M$101,M9)>1,"⚠ 重复","唯一")
A15: A013 | B15: ⬜ | C15: 9 | D15: ドアノブの火花 | E15: 会咬人的门把手 | F15: I 组建期 | G15: 核心连载 | H15: 校园·图书馆 | I15: 1月 | J15: 志郎 | K15: 光·慧美·志郎·珣（+瑆 笔记） | L15: 电磁 | M15: 材料 | N15: 气象 | O15: 导电性 + 干燥湿度 + 静电 | P15: 实验 | R15: =IF(COUNTIF($M$2:$M$101,M10)>1,"⚠ 重复","唯一")
A16: A014 | B16: ⬜ | C16: 10 | D16: 黒板の染み | E16: 黑板上的印记 | F16: I 组建期 | G16: 核心连载 | H16: 校园 | I16: 3月学年末 | J16: 慧美 | K16: 光·慧美·志郎·珣（+瑆 笔记） | L16: 化学 | M16: 材料 | N16: 光学 | O16: 相似相溶 + 窗格投影 + 表面张力 | P16: 实验 | R16: =IF(COUNTIF($M$2:$M$101,M11)>1,"⚠ 重复","唯一")
A17: A015 | B17: ⬜ | C17: 11 | D17: 廊下の口笛 | E17: 走廊的口哨声 | F17: I 组建期 | G17: 核心连载 | H17: 校园 | I17: 1月 | J17: 珣 | K17: 光·慧美·志郎·珣（+瑆 笔记） | L17: 声学 | M17: 流体 | N17: 建筑 | O17: 开口位置 + 狭管加速 + 风啸效应 | P17: 微观 | R17: =IF(COUNTIF($M$2:$M$101,M12)>1,"⚠ 重复","唯一")
A18: A016 | B18: ⬜ | C18: 12 | D18: 浮かぶ氷 | E18: 浮起来的冰块 | F18: I 组建期 | G18: 核心连载 | H18: 校园·给食 | I18: 2月 | J18: 慧美·志郎 | K18: 光·慧美·志郎·珣（+瑆 笔记） | L18: 力学 | M18: 热学 | N18: 材料 | O18: 密度差 + 浮力 + 融化吸热 | P18: 实验 | R18: =IF(COUNTIF($M$2:$M$101,M13)>1,"⚠ 重复","唯一")
A19: A017 | B19: ⬜ · ★L01 | C19: 13 | D19: 葛西さんの古地図 | E19: 葛西爷爷的旧地图 | F19: I 组建期 | G19: 核心连载 | H19: 社区 | I19: 3月 | J19: 葛西·珣 | K19: 光·慧美·志郎·珣·葛西（+瑆 笔记） | L19: 地理 | M19: 历史 | N19: 光学 | O19: 地图比例尺 + 地貌变迁 + 颜料褪色 | P19: 溯源+人际 | Q19: 种子①(旧地图) | R19: =IF(COUNTIF($M$2:$M$101,M14)>1,"⚠ 重复","唯一")
A20: A018 | B20: ⬜ | C20: 14 | D20: 曲がるストロー | E20: 弯曲的吸管 | F20: I 组建期 | G20: 外延单元 | H20: 家庭 | I20: 4月 | J20: 珣·瑆 | K20: 光·慧美·志郎·珣（+瑆 笔记） | L20: 光学 | M20: 流体 | N20: 感知 | O20: 折射 + 液面 + 视错觉 | P20: 感知预热 | R20: =IF(COUNTIF($M$2:$M$101,M15)>1,"⚠ 重复","唯一")
A21: A019 | B21: ⬜ | C21: 15 | D21: におう教室 | E21: 有味道的教室 | F21: I 组建期 | G21: 核心连载 | H21: 校园 | I21: 5月 | J21: 慧美 | K21: 光·慧美·志郎·珣（+瑆 笔记） | L21: 食品化学 | M21: 微生物 | N21: 气象 | O21: 发酵气味 + 菌群 + 通风对流 | P21: 实验 | R21: =IF(COUNTIF($M$2:$M$101,M16)>1,"⚠ 重复","唯一")
A22: A020 | B22: ⬜ | C22: 16 | D22: 影絵の怪 | E22: 影子戏的怪影 | F22: I 组建期 | G22: 核心连载 | H22: 校园·社区 | I22: 6月 | J22: 珣 | K22: 光·慧美·志郎·珣（+瑆 笔记） | L22: 光学 | M22: 几何 | N22: 感知 | O22: 多光源影 + 投影几何 + 视错觉 | P22: 感知 | R22: =IF(COUNTIF($M$2:$M$101,M17)>1,"⚠ 重复","唯一")
A23: A021 | B23: ⬜ | C23: 17 | D23: 動く植木 | E23: 会动的盆栽 | F23: I 组建期 | G23: 核心连载 | H23: 校园·植物角 | I23: 7月 | J23: 珣 | K23: 光·慧美·志郎·珣（+瑆 笔记） | L23: 植物 | M23: 光学 | N23: 生物 | O23: 光周期 + 向光性 + 膨压运动 | P23: 微观 | R23: =IF(COUNTIF($M$2:$M$101,M18)>1,"⚠ 重复","唯一")
A24: A022 | B24: ⬜ | C24: 18 | D24: 鳥のものまね | E24: 鸟的口技 | F24: I 组建期 | G24: 外延单元 | H24: 社区·公园 | I24: 9月 | J24: 珣 | K24: 光·慧美·志郎·珣（+瑆 笔记） | L24: 动物 | M24: 声学 | N24: 人体 | O24: 听觉范围 + 声音频率 + 鸟类发声 | P24: 微观 | R24: =IF(COUNTIF($M$2:$M$101,M19)>1,"⚠ 重复","唯一")
A25: A023 | B25: ⬜ | C25: 19 | D25: 濡れない傘 | E25: 淋不湿的伞 | F25: I 组建期 | G25: 外延单元 | H25: 家庭 | I25: 10月秋雨 | J25: 志郎 | K25: 光·慧美·志郎·珣（+瑆 笔记） | L25: 材料 | M25: 流体 | N25: 化学 | O25: 涂层化学 + 疏水表面 + 表面张力 | P25: 结构 | R25: =IF(COUNTIF($M$2:$M$101,M20)>1,"⚠ 重复","唯一")
A26: A024 | B26: ⬜ | C26: 20 | D26: 消えた虹 | E26: 消失的彩虹 | F26: I 组建期 | G26: 核心连载 | H26: 校园 | I26: 11月 | J26: 慧美·珣 | K26: 光·慧美·志郎·珣（+瑆 笔记） | L26: 光学 | M26: 气象 | N26: 几何 | O26: 太阳角 + 水滴折射 + 色散 | P26: 实验+微观 | R26: =IF(COUNTIF($M$2:$M$101,M21)>1,"⚠ 重复","唯一")
A27: B001 | B27: ⬜ | C27: 21 | D27: 名古屋城のしゃちほこ | E27: 名古屋城的金鯱 | F27: I 组建期 | G27: 外延单元 | H27: 城市特典·远足 | I27: 4月 | J27: 志郎·珣 | K27: 光·慧美·志郎·珣（+瑆 笔记） | L27: 建筑 | M27: 材料 | N27: 历史 | O27: 抗震结构 + 避雷原理 + 金属氧化 | P27: 结构+溯源 | R27: =IF(COUNTIF($M$2:$M$101,M22)>1,"⚠ 重复","唯一")
A28: B002 | B28: ⬜ | C28: 22 | D28: 熱田の森 | E28: 热田神宫的森林 | F28: I 组建期 | G28: 外延单元 | H28: 城市特典·远足 | I28: 5月 | J28: 珣 | K28: 光·慧美·志郎·珣（+瑆 笔记） | L28: 生物 | M28: 气象 | N28: 声学 | O28: 树冠隔音 + 森林微气候 + 空气湿度 | P28: 微观 | R28: =IF(COUNTIF($M$2:$M$101,M23)>1,"⚠ 重复","唯一")
A29: B003 | B29: ⬜ | C29: 23 | D29: 犬山城の天守 | E29: 犬山城天守 | F29: I 组建期 | G29: 外延单元 | H29: 城市特典·修学旅行 | I29: 6月 | J29: 志郎·珣 | K29: 光·慧美·志郎·珣（+瑆 笔记） | L29: 力学 | M29: 建筑 | N29: 工程 | O29: 抗震阻尼 + 木构榫卯 + 重心平衡 | P29: 结构还原 | R29: =IF(COUNTIF($M$2:$M$101,M24)>1,"⚠ 重复","唯一")
A30: B004 | B30: ⬜ | C30: 24 | D30: リニア館の磁気 | E30: 磁浮馆的磁力 | F30: I 组建期 | G30: 外延单元 | H30: 城市特典·科学馆 | I30: 7月 | J30: 慧美·珣 | K30: 光·慧美·志郎·珣（+瑆 笔记） | L30: 电磁 | M30: 工程 | N30: 力学 | O30: 涡流 + 电磁感应 + 磁悬浮 | P30: 实验 | R30: =IF(COUNTIF($M$2:$M$101,M25)>1,"⚠ 重复","唯一")
A31: B005 | B31: ⬜ | C31: 25 | D31: 動物園の鳴き声 | E31: 东山动物园的叫声 | F31: I 组建期 | G31: 外延单元 | H31: 城市特典 | I31: 8月 | J31: 珣 | K31: 光·慧美·志郎·珣（+瑆 笔记） | L31: 动物 | M31: 声学 | N31: 行为 | O31: 共鸣腔 + 动物发声 + 行为信号 | P31: 微观 | R31: =IF(COUNTIF($M$2:$M$101,M26)>1,"⚠ 重复","唯一")
A32: B006 | B32: ⬜ | C32: 26 | D32: プラネタリウムの北 | E32: 天文馆的北方 | F32: I 组建期 | G32: 外延单元 | H32: 城市特典·天文 | I32: 9月 | J32: 慧美·珣 | K32: 光·慧美·志郎·珣（+瑆 笔记） | L32: 天文 | M32: 地理 | N32: 数学 | O32: 北极星定位 + 周日视运动 + 极轴 | P32: 实验 | R32: =IF(COUNTIF($M$2:$M$101,M27)>1,"⚠ 重复","唯一")
A33: B007 | B33: ⬜ · ★ | C33: 27 | D33: 美術館の青 | E33: 美术馆的蓝色 | F33: I 组建期 | G33: 外延单元 | H33: 城市特典·主题 | I33: 10月 | J33: 珣 | K33: 光·慧美·志郎·珣（+瑆 笔记） | L33: 色彩 | M33: 化学 | N33: 光学 | O33: 光反射 + 光致变色 + 矿物颜料 | P33: 微观 | Q33: 种子②(矿物颜料) | R33: =IF(COUNTIF($M$2:$M$101,M28)>1,"⚠ 重复","唯一")
A34: B008 | B34: ⬜ | C34: 28 | D34: 川の四六分水 | E34: 河边的四六分水 | F34: I 组建期 | G34: 外延单元 | H34: 城市特典·治水 | I34: 11月 | J34: 志郎 | K34: 光·慧美·志郎·珣（+瑆 笔记） | L34: 流体 | M34: 工程 | N34: 地理 | O34: 分水力学 + 河床形态 + 流速分配 | P34: 结构 | R34: =IF(COUNTIF($M$2:$M$101,M29)>1,"⚠ 重复","唯一")
A35: B009 | B35: ⬜ | C35: 29 | D35: 味噌蔵の温度 | E35: 味噌作坊的温度 | F35: I 组建期 | G35: 外延单元 | H35: 城市特典·食农 | I35: 12月 | J35: 慧美 | K35: 光·慧美·志郎·珣（+瑆 笔记） | L35: 食品化学 | M35: 微生物 | N35: 热学 | O35: 味噌发酵 + 恒温控制 + 熟成菌群 | P35: 实验 | R35: =IF(COUNTIF($M$2:$M$101,M30)>1,"⚠ 重复","唯一")
A36: B010 | B36: ⬜ · ★ | C36: 30 | D36: 古い鐘の音 | E36: 古寺的钟声 | F36: I 组建期 | G36: 外延单元 | H36: 城市特典·历史 | I36: 1月初詣 | J36: 珣·葛西 | K36: 光·慧美·志郎·珣·葛西（+瑆 笔记） | L36: 声学 | M36: 材料 | N36: 历史 | O36: 合金成分 + 声衰减 + 钟体共振 | P36: 微观+溯源 | Q36: 种子③(古钟合金) | R36: =IF(COUNTIF($M$2:$M$101,M31)>1,"⚠ 重复","唯一")
A37: A025 | B37: ⬜ | C37: 31 | D37: 夏祭りの提灯 | E37: 夏日祭的灯笼 | F37: I 组建期 | G37: 外延单元 | H37: 季节特别·祭典 | I37: 7月 | J37: 慧美·珣 | K37: 光·慧美·志郎·珣（+瑆 笔记） | L37: 热学 | M37: 流体 | N37: 光学 | O37: 光晕散射 + 热对流 + 空气浮力 | P37: 实验 | R37: =IF(COUNTIF($M$2:$M$101,M32)>1,"⚠ 重复","唯一")
A38: A026 | B38: ⬜ | C38: 32 | D38: 花火の遅れ | E38: 烟花的延迟 | F38: I 组建期 | G38: 外延单元 | H38: 季节特别·祭典 | I38: 8月 | J38: 珣 | K38: 光·慧美·志郎·珣（+瑆 笔记） | L38: 声学 | M38: 光学 | N38: 数学 | O38: 光速差 + 声速 + 测距计算 | P38: 微观+实验 | R38: =IF(COUNTIF($M$2:$M$101,M33)>1,"⚠ 重复","唯一")
A39: A027 | B39: ⬜ | C39: 33 | D39: 体育祭の白線 | E39: 运动会的白线 | F39: I 组建期 | G39: 外延单元 | H39: 季节特别·校园 | I39: 9月运动会 | J39: 慧美·志郎 | K39: 光·慧美·志郎·珣（+瑆 笔记） | L39: 化学 | M39: 材料 | N39: 几何 | O39: 直线测放 + 石灰反应 + 粉末附着 | P39: 实验 | R39: =IF(COUNTIF($M$2:$M$101,M34)>1,"⚠ 重复","唯一")
A40: A028 | B40: ⬜ | C40: 34 | D40: 落ち葉の渦 | E40: 落叶的漩涡 | F40: I 组建期 | G40: 外延单元 | H40: 季节特别·秋 | I40: 11月 | J40: 珣 | K40: 光·慧美·志郎·珣（+瑆 笔记） | L40: 流体 | M40: 气象 | N40: 力学 | O40: 卡门涡街 + 涡流脱落 + 风压 | P40: 微观 | R40: =IF(COUNTIF($M$2:$M$101,M35)>1,"⚠ 重复","唯一")
...

Sheet 知识域容量
A1: 知识域 | B1: 前100篇出现次数 | C1: 占比 | D1: 说明
A2: 人体 | B2: =COUNTIF(前100篇台账!$J$2:$L$101,A2) | C2: =B2/300 | D2: 组合层去重；单域可在不同三元组中复现
A3: 光学 | B3: =COUNTIF(前100篇台账!$J$2:$L$101,A3) | C3: =B3/300 | D3: 组合层去重；单域可在不同三元组中复现
A4: 几何 | B4: =COUNTIF(前100篇台账!$J$2:$L$101,A4) | C4: =B4/300 | D4: 组合层去重；单域可在不同三元组中复现
A5: 力学 | B5: =COUNTIF(前100篇台账!$J$2:$L$101,A5) | C5: =B5/300 | D5: 组合层去重；单域可在不同三元组中复现
A6: 动物 | B6: =COUNTIF(前100篇台账!$J$2:$L$101,A6) | C6: =B6/300 | D6: 组合层去重；单域可在不同三元组中复现
A7: 化学 | B7: =COUNTIF(前100篇台账!$J$2:$L$101,A7) | C7: =B7/300 | D7: 组合层去重；单域可在不同三元组中复现
A8: 历史 | B8: =COUNTIF(前100篇台账!$J$2:$L$101,A8) | C8: =B8/300 | D8: 组合层去重；单域可在不同三元组中复现
A9: 图书馆学 | B9: =COUNTIF(前100篇台账!$J$2:$L$101,A9) | C9: =B9/300 | D9: 组合层去重；单域可在不同三元组中复现
A10: 地理 | B10: =COUNTIF(前100篇台账!$J$2:$L$101,A10) | C10: =B10/300 | D10: 组合层去重；单域可在不同三元组中复现
A11: 地质 | B11: =COUNTIF(前100篇台账!$J$2:$L$101,A11) | C11: =B11/300 | D11: 组合层去重；单域可在不同三元组中复现
A12: 声学 | B12: =COUNTIF(前100篇台账!$J$2:$L$101,A12) | C12: =B12/300 | D12: 组合层去重；单域可在不同三元组中复现
A13: 天文 | B13: =COUNTIF(前100篇台账!$J$2:$L$101,A13) | C13: =B13/300 | D13: 组合层去重；单域可在不同三元组中复现
... A37: 食品化学 | B37: =COUNTIF(前100篇台账!$J$2:$L$101,A37) | C37: =B37/300 | D37: 组合层去重；单域可在不同三元组中复现
A38: 合计（应=300） | B38: =SUM(B2:B37)

Sheet 说明
A1: 《学堂奇事録》· 前100篇原理去重台账
A3: 范围：第 1–100 篇。1–40 = I 组建期；41–90 = II 感知期；91–100 = III 拓展期开篇。
A4: 51–100 为城市/历史复合密集区：载体重心压在「城市特典 + 社区历史长线」，葛西记忆线在此逐段展开。
A5: 行底色：黄=长线种子/收束点；浅绿=II 感知期(51–90)；浅橙=III 拓展期(91–100)。
A7: 去重机制：
A8: · 「三原理三元组（标准化）」= 三个核心原理排序后用 + 连接，是去重唯一键。
A9: · 「重复校验」=COUNTIF 自动比对全 100 行；当前应全部显示「唯一」。
A10: · 去重在「组合」层级——单域（气象、光学、历史…）可在不同三元组中复现，三元组本身唯一即可。
A12: 人物加入节点：陸珣=第1篇；山本理紗=第41篇；中谷琦=第53篇；葛西全藏=历史/旧物案不定期出场。
A13: 陸瑆成长：41篇起从记录者转向独立推理，III 拓展期多次领衔（91/93/95/100）。
A15: 新增第 101 篇及以后：
A16: 1. 定三个核心原理 → 排序写入「三原理三元组」列。
... A23: · zip-2 前100篇 · 增列 正典ID/gate_pass · Vol1 A001–A005 · #1→C001 · #100→D001
