Workbook

Sheet 前50篇台账
A1: 案号 | B1: 篇名（日） | C1: 篇名（中） | D1: 阶段 | E1: 层级 | F1: 载体 | G1: 季节 | H1: 领衔 | I1: 参与全员 | J1: 知识域 1 | K1: 知识域 2 | L1: 知识域 3 | M1: 三原理三元组（标准化） | N1: 主范式 | O1: 长线标记 | P1: 重复校验
A2: 1 | B2: 濡れる椅子 | C2: 总是湿的椅子 | D2: I 组建期 | E2: 核心连载 | F2: 校园 | G2: 4月 | H2: 光·慧美·珣 | I2: 光·慧美·志郎·珣（+瑆 笔记） | J2: 热学 | K2: 热传导 | L2: 气象 | M2: 窗框热传导 + 结露 + 露点湿度 | N2: 实验+微观 | O2: 入社案 | P2: =IF(COUNTIF($M$2:$M$51,M2)>1,"⚠ 重复","唯一") -> 唯一
A3: 2 | B3: 転がる消しゴム | C3: 谁偷了橡皮 | D3: I 组建期 | E3: 核心连载 | F3: 校园 | G3: 5月 | H3: 志郎 | I3: 光·慧美·志郎·珣（+瑆 笔记） | J3: 力学 | K3: 材料 | L3: 行为 | M3: 摩擦力 + 斜面滚动 + 行为习惯 | N3: 结构还原 | P3: =IF(COUNTIF($M$2:$M$51,M3)>1,"⚠ 重复","唯一") -> 唯一
A4: 3 | B4: アリの行列 | C4: 蚂蚁的队列 | D4: I 组建期 | E4: 核心连载 | F4: 校园·操场 | G4: 6月梅雨 | H4: 珣 | I4: 光·慧美·志郎·珣（+瑆 笔记） | J4: 生物 | K4: 化学 | L4: 气象 | M4: 信息素挥发 + 昆虫信息素 + 湿度扩散 | N4: 微观领域 | P4: =IF(COUNTIF($M$2:$M$51,M4)>1,"⚠ 重复","唯一") -> 唯一
A5: 4 | B5: 音楽室の和音 | C5: 音乐教室的怪声 | D5: I 组建期 | E5: 核心连载 | F5: 校园 | G5: 7月 | H5: 珣 | I5: 光·慧美·志郎·珣（+瑆 笔记） | J5: 声学 | K5: 音乐 | L5: 材料 | M5: 共振 + 和弦泛音 + 固体传声 | N5: 微观 | P5: =IF(COUNTIF($M$2:$M$51,M5)>1,"⚠ 重复","唯一") -> 唯一
A6: 5 | B6: 旗竿の影 | C6: 歪掉的旗杆影子 | D6: I 组建期 | E6: 核心连载 | F6: 校园·操场 | G6: 10月运动会 | H6: 慧美·珣 | I6: 光·慧美·志郎·珣（+瑆 笔记） | J6: 天文 | K6: 地理 | L6: 数学 | M6: 几何投影 + 太阳高度角 + 纬度时差 | N6: 实验+结构 | P6: =IF(COUNTIF($M$2:$M$51,M6)>1,"⚠ 重复","唯一") -> 唯一
A7: 6 | B7: 蛇口のぬるま湯 | C7: 水龙头里的温水 | D7: I 组建期 | E7: 核心连载 | F7: 校园 | G7: 8月 | H7: 志郎 | I7: 光·慧美·志郎·珣（+瑆 笔记） | J7: 热学 | K7: 地质 | L7: 工程 | M7: 土壤比热 + 管道埋深 + 管道热传导 | N7: 结构还原 | P7: =IF(COUNTIF($M$2:$M$51,M7)>1,"⚠ 重复","唯一") -> 唯一
A8: 7 | B8: 植木鉢の白い骨 | C8: 花盆里的白骨 | D8: I 组建期 | E8: 核心连载 | F8: 校园·植物角 | G8: 11月 | H8: 珣 | I8: 光·慧美·志郎·珣（+瑆 笔记） | J8: 微生物 | K8: 植物 | L8: 化学 | M8: 共生关系 + 真菌菌丝 + 菌丝代谢 | N8: 微观 | P8: =IF(COUNTIF($M$2:$M$51,M8)>1,"⚠ 重复","唯一") -> 唯一
A9: 8 | B9: 遅れる時計 | C9: 不走的钟 | D9: I 组建期 | E9: 核心连载 | F9: 校园 | G9: 12月 | H9: 慧美·珣 | I9: 光·慧美·志郎·珣（+瑆 笔记） | J9: 电子 | K9: 热学 | L9: 数学 | M9: 温差 + 石英晶振温度特性 + 误差累积 | N9: 实验+微观 | P9: =IF(COUNTIF($M$2:$M$51,M9)>1,"⚠ 重复","唯一") -> 唯一
A10: 9 | B10: ドアノブの火花 | C10: 会咬人的门把手 | D10: I 组建期 | E10: 核心连载 | F10: 校园·图书馆 | G10: 1月 | H10: 志郎 | I10: 光·慧美·志郎·珣（+瑆 笔记） | J10: 电磁 | K10: 材料 | L10: 气象 | M10: 导电性 + 干燥湿度 + 静电 | N10: 实验 | P10: =IF(COUNTIF($M$2:$M$51,M10)>1,"⚠ 重复","唯一") -> 唯一
A11: 10 | B11: 黒板の染み | C11: 黑板上的印记 | D11: I 组建期 | E11: 核心连载 | F11: 校园 | G11: 3月学年末 | H11: 慧美 | I11: 光·慧美·志郎·珣（+瑆 笔记） | J11: 化学 | K11: 材料 | L11: 光学 | M11: 相似相溶 + 窗格投影 + 表面张力 | N11: 实验 | P11: =IF(COUNTIF($M$2:$M$51,M11)>1,"⚠ 重复","唯一") -> 唯一
A12: 11 | B12: 廊下の口笛 | C12: 走廊的口哨声 | D12: I 组建期 | E12: 核心连载 | F12: 校园 | G12: 1月 | H12: 珣 | I12: 光·慧美·志郎·珣（+瑆 笔记） | J12: 声学 | K12: 流体 | L12: 建筑 | M12: 开口位置 + 狭管加速 + 风啸效应 | N12: 微观 | P12: =IF(COUNTIF($M$2:$M$51,M12)>1,"⚠ 重复","唯一") -> 唯一
A13: 12 | B13: 浮かぶ氷 | C13: 浮起来的冰块 | D13: I 组建期 | E13: 核心连载 | F13: 校园·给食 | G13: 2月 | H13: 慧美·志郎 | I13: 光·慧美·志郎·珣（+瑆 笔记） | J13: 力学 | K13: 热学 | L13: 材料 | M13: 密度差 + 浮力 + 融化吸热 | N13: 实验 | P13: =IF(COUNTIF($M$2:$M$51,M13)>1,"⚠ 重复","唯一") -> 唯一
A14: 13 | B14: 葛西さんの古地図 | C14: 葛西爷爷的旧地图 | D14: I 组建期 | E14: 核心连载 | F14: 社区 | G14: 3月 | H14: 葛西·珣 | I14: 光·慧美·志郎·珣·葛西（+瑆 笔记） | J14: 地理 | K14: 历史 | L14: 光学 | M14: 地图比例尺 + 地貌变迁 + 颜料褪色 | N14: 溯源+人际 | O14: 种子①(旧地图) | P14: =IF(COUNTIF($M$2:$M$51,M14)>1,"⚠ 重复","唯一") -> 唯一
A15: 14 | B15: 曲がるストロー | C15: 弯曲的吸管 | D15: I 组建期 | E15: 外延单元 | F15: 家庭 | G15: 4月 | H15: 珣·瑆 | I15: 光·慧美·志郎·珣（+瑆 笔记） | J15: 光学 | K15: 流体 | L15: 感知 | M15: 折射 + 液面 + 视错觉 | N15: 感知预热 | P15: =IF(COUNTIF($M$2:$M$51,M15)>1,"⚠ 重复","唯一") -> 唯一
A16: 15 | B16: におう教室 | C16: 有味道的教室 | D16: I 组建期 | E16: 核心连载 | F16: 校园 | G16: 5月 | H16: 慧美 | I16: 光·慧美·志郎·珣（+瑆 笔记） | J16: 食品化学 | K16: 微生物 | L16: 气象 | M16: 发酵气味 + 菌群 + 通风对流 | N16: 实验 | P16: =IF(COUNTIF($M$2:$M$51,M16)>1,"⚠ 重复","唯一") -> 唯一
A17: 16 | B17: 影絵の怪 | C17: 影子戏的怪影 | D17: I 组建期 | E17: 核心连载 | F17: 校园·社区 | G17: 6月 | H17: 珣 | I17: 光·慧美·志郎·珣（+瑆 笔记） | J17: 光学 | K17: 几何 | L17: 感知 | M17: 多光源影 + 投影几何 + 视错觉 | N17: 感知 | P17: =IF(COUNTIF($M$2:$M$51,M17)>1,"⚠ 重复","唯一") -> 唯一
A18: 17 | B18: 動く植木 | C18: 会动的盆栽 | D18: I 组建期 | E18: 核心连载 | F18: 校园·植物角 | G18: 7月 | H18: 珣 | I18: 光·慧美·志郎·珣（+瑆 笔记） | J18: 植物 | K18: 光学 | L18: 生物 | M18: 光周期 + 向光性 + 膨压运动 | N18: 微观 | P18: =IF(COUNTIF($M$2:$M$51,M18)>1,"⚠ 重复","唯一") -> 唯一
A19: 18 | B19: 鳥のものまね | C19: 鸟的口技 | D19: I 组建期 | E19: 外延单元 | F19: 社区·公园 | G19: 9月 | H19: 珣 | I19: 光·慧美·志郎·珣（+瑆 笔记） | J19: 动物 | K19: 声学 | L19: 人体 | M19: 听觉范围 + 声音频率 + 鸟类发声 | N19: 微观 | P19: =IF(COUNTIF($M$2:$M$51,M19)>1,"⚠ 重复","唯一") -> 唯一
A20: 19 | B20: 濡れない傘 | C20: 淋不湿的伞 | D20: I 组建期 | E20: 外延单元 | F20: 家庭 | G20: 10月秋雨 | H20: 志郎 | I20: 光·慧美·志郎·珣（+瑆 笔记） | J20: 材料 | K20: 流体 | L20: 化学 | M20: 涂层化学 + 疏水表面 + 表面张力 | N20: 结构 | P20: =IF(COUNTIF($M$2:$M$51,M20)>1,"⚠ 重复","唯一") -> 唯一
A21: 20 | B21: 消えた虹 | C21: 消失的彩虹 | D21: I 组建期 | E21: 核心连载 | F21: 校园 | G21: 11月 | H21: 慧美·珣 | I21: 光·慧美·志郎·珣（+瑆 笔记） | J21: 光学 | K21: 气象 | L21: 几何 | M21: 太阳角 + 水滴折射 + 色散 | N21: 实验+微观 | P21: =IF(COUNTIF($M$2:$M$51,M21)>1,"⚠ 重复","唯一") -> 唯一
A22: 21 | B22: 名古屋城のしゃちほこ | C22: 名古屋城的金鯱 | D22: I 组建期 | E22: 外延单元 | F22: 城市特典·远足 | G22: 4月 | H22: 志郎·珣 | I22: 光·慧美·志郎·珣（+瑆 笔记） | J22: 建筑 | K22: 材料 | L22: 历史 | M22: 抗震结构 + 避雷原理 + 金属氧化 | N22: 结构+溯源 | P22: =IF(COUNTIF($M$2:$M$51,M22)>1,"⚠ 重复","唯一") -> 唯一
A23: 22 | B23: 熱田の森 | C23: 热田神宫的森林 | D23: I 组建期 | E23: 外延单元 | F23: 城市特典·远足 | G23: 5月 | H23: 珣 | I23: 光·慧美·志郎·珣（+瑆 笔记） | J23: 生物 | K23: 气象 | L23: 声学 | M23: 树冠隔音 + 森林微气候 + 空气湿度 | N23: 微观 | P23: =IF(COUNTIF($M$2:$M$51,M23)>1,"⚠ 重复","唯一") -> 唯一
A24: 23 | B24: 犬山城の天守 | C24: 犬山城天守 | D24: I 组建期 | E24: 外延单元 | F24: 城市特典·修学旅行 | G24: 6月 | H24: 志郎·珣 | I24: 光·慧美·志郎·珣（+瑆 笔记） | J24: 力学 | K24: 建筑 | L24: 工程 | M24: 抗震阻尼 + 木构榫卯 + 重心平衡 | N24: 结构还原 | P24: =IF(COUNTIF($M$2:$M$51,M24)>1,"⚠ 重复","唯一") -> 唯一
A25: 24 | B25: リニア館の磁気 | C25: 磁浮馆的磁力 | D25: I 组建期 | E25: 外延单元 | F25: 城市特典·科学馆 | G25: 7月 | H25: 慧美·珣 | I25: 光·慧美·志郎·珣（+瑆 笔记） | J25: 电磁 | K25: 工程 | L25: 力学 | M25: 涡流 + 电磁感应 + 磁悬浮 | N25: 实验 | P25: =IF(COUNTIF($M$2:$M$51,M25)>1,"⚠ 重复","唯一") -> 唯一
A26: 25 | B26: 動物園の鳴き声 | C26: 东山动物园的叫声 | D26: I 组建期 | E26: 外延单元 | F26: 城市特典 | G26: 8月 | H26: 珣 | I26: 光·慧美·志郎·珣（+瑆 笔记） | J26: 动物 | K26: 声学 | L26: 行为 | M26: 共鸣腔 + 动物发声 + 行为信号 | N26: 微观 | P26: =IF(COUNTIF($M$2:$M$51,M26)>1,"⚠ 重复","唯一") -> 唯一
A27: 26 | B27: プラネタリウムの北 | C27: 天文馆的北方 | D27: I 组建期 | E27: 外延单元 | F27: 城市特典·天文 | G27: 9月 | H27: 慧美·珣 | I27: 光·慧美·志郎·珣（+瑆 笔记） | J27: 天文 | K27: 地理 | L27: 数学 | M27: 北极星定位 + 周日视运动 + 极轴 | N27: 实验 | P27: =IF(COUNTIF($M$2:$M$51,M27)>1,"⚠ 重复","唯一") -> 唯一
A28: 27 | B28: 美術館の青 | C28: 美术馆的蓝色 | D28: I 组建期 | E28: 外延单元 | F28: 城市特典·主题 | G28: 10月 | H28: 珣 | I28: 光·慧美·志郎·珣（+瑆 笔记） | J28: 色彩 | K28: 化学 | L28: 光学 | M28: 光反射 + 光致变色 + 矿物颜料 | N28: 微观 | O28: 种子②(矿物颜料) | P28: =IF(COUNTIF($M$2:$M$51,M28)>1,"⚠ 重复","唯一") -> 唯一
A29: 28 | B29: 川の四六分水 | C29: 河边的四六分水 | D29: I 组建期 | E29: 外延单元 | F29: 城市特典·治水 | G29: 11月 | H29: 志郎 | I29: 光·慧美·志郎·珣（+瑆 笔记） | J29: 流体 | K29: 工程 | L29: 地理 | M29: 分水力学 + 河床形态 + 流速分配 | N29: 结构 | P29: =IF(COUNTIF($M$2:$M$51,M29)>1,"⚠ 重复","唯一") -> 唯一
A30: 29 | B30: 味噌蔵の温度 | C30: 味噌作坊的温度 | D30: I 组建期 | E30: 外延单元 | F30: 城市特典·食农 | G30: 12月 | H30: 慧美 | I30: 光·慧美·志郎·珣（+瑆 笔记） | J30: 食品化学 | K30: 微生物 | L30: 热学 | M30: 味噌发酵 + 恒温控制 + 熟成菌群 | N30: 实验 | P30: =IF(COUNTIF($M$2:$M$51,M30)>1,"⚠ 重复","唯一") -> 唯一
A31: 30 | B31: 古い鐘の音 | C31: 古寺的钟声 | D31: I 组建期 | E31: 外延单元 | F31: 城市特典·历史 | G31: 1月初詣 | H31: 珣·葛西 | I31: 光·慧美·志郎·珣·葛西（+瑆 笔记） | J31: 声学 | K31: 材料 | L31: 历史 | M31: 合金成分 + 声衰减 + 钟体共振 | N31: 微观+溯源 | O31: 种子③(古钟合金) | P31: =IF(COUNTIF($M$2:$M$51,M31)>1,"⚠ 重复","唯一") -> 唯一
A32: 31 | B32: 夏祭りの提灯 | C32: 夏日祭的灯笼 | D32: I 组建期 | E32: 外延单元 | F32: 季节特别·祭典 | G32: 7月 | H32: 慧美·珣 | I32: 光·慧美·志郎·珣（+瑆 笔记） | J32: 热学 | K32: 流体 | L32: 光学 | M32: 光晕散射 + 热对流 + 空气浮力 | N32: 实验 | P32: =IF(COUNTIF($M$2:$M$51,M32)>1,"⚠ 重复","唯一") -> 唯一
A33: 32 | B33: 花火の遅れ | C33: 烟花的延迟 | D33: I 组建期 | E33: 外延单元 | F33: 季节特别·祭典 | G33: 8月 | H33: 珣 | I33: 光·慧美·志郎·珣（+瑆 笔记） | J33: 声学 | K33: 光学 | L33: 数学 | M33: 光速差 + 声速 + 测距计算 | N33: 微观+实验 | P33: =IF(COUNTIF($M$2:$M$51,M33)>1,"⚠ 重复","唯一") -> 唯一
A34: 33 | B34: 体育祭の白線 | C34: 运动会的白线 | D34: I 组建期 | E34: 外延单元 | F34: 季节特别·校园 | G34: 9月运动会 | H34: 慧美·志郎 | I34: 光·慧美·志郎·珣（+瑆 笔记） | J34: 化学 | K34: 材料 | L34: 几何 | M34: 直线测放 + 石灰反应 + 粉末附着 | N34: 实验 | P34: =IF(COUNTIF($M$2:$M$51,M34)>1,"⚠ 重复","唯一") -> 唯一
A35: 34 | B35: 落ち葉の渦 | C35: 落叶的漩涡 | D35: I 组建期 | E35: 外延单元 | F35: 季节特别·秋 | G35: 11月 | H35: 珣 | I35: 光·慧美·志郎·珣（+瑆 笔记） | J35: 流体 | K35: 气象 | L35: 力学 | M35: 卡门涡街 + 涡流脱落 + 风压 | N35: 微观 | P35: =IF(COUNTIF($M$2:$M$51,M35)>1,"⚠ 重复","唯一") -> 唯一
A36: 35 | B36: 給食のゼリー | C36: 给食的果冻 | D36: I 组建期 | E36: 外延单元 | F36: 主题专项·食品 | G36: 1月 | H36: 慧美 | I36: 光·慧美·志郎·珣（+瑆 笔记） | J36: 食品化学 | K36: 材料 | L36: 生物 | M36: 凝胶化 + 温度控制 + 蛋白酶 | N36: 实验 | P36: =IF(COUNTIF($M$2:$M$51,M36)>1,"⚠ 重复","唯一") -> 唯一
A37: 36 | B37: 図書室の迷子本 | C37: 图书室的迷路书 | D37: I 组建期 | E37: 外延单元 | F37: 主题专项·图书馆学 | G37: 2月 | H37: 瑆 | I37: 光·慧美·志郎·珣（+瑆 笔记） | J37: 图书馆学 | K37: 逻辑 | L37: 心理 | M37: 借阅行为 + 图书分类 + 索书号系统 | N37: 人际+逻辑 | P37: =IF(COUNTIF($M$2:$M$51,M37)>1,"⚠ 重复","唯一") -> 唯一
A38: 37 | B38: 自由研究の失敗 | C38: 自由研究的失败 | D38: I 组建期 | E38: 外延单元 | F38: 季节特别·暑假 | G38: 8月 | H38: 慧美 | I38: 光·慧美·志郎·珣（+瑆 笔记） | J38: 实验方法 | K38: 数学 | L38: 逻辑 | M38: 实验误差 + 对照实验 + 概率思维 | N38: 实验 | P38: =IF(COUNTIF($M$2:$M$51,M38)>1,"⚠ 重复","唯一") -> 唯一
A39: 38 | B39: 雪の朝の足跡 | C39: 雪天早晨的脚印 | D39: I 组建期 | E39: 外延单元 | F39: 季节特别·冬 | G39: 12月 | H39: 珣 | I39: 光·慧美·志郎·珣（+瑆 笔记） | J39: 物态 | K39: 热学 | L39: 感知 | M39: 压力融化 + 痕迹错视 + 雪面热传导 | N39: 微观 | P39: =IF(COUNTIF($M$2:$M$51,M39)>1,"⚠ 重复","唯一") -> 唯一
A40: 39 | B40: 風の日の窓 | C40: 刮风天的窗户 | D40: I 组建期 | E40: 外延单元 | F40: 主题专项·建筑物理 | G40: 3月春一番 | H40: 志郎 | I40: 光·慧美·志郎·珣（+瑆 笔记） | J40: 流体 | K40: 建筑 | L40: 声学 | M40: 伯努利效应 + 建筑风压 + 缝隙啸声 | N40: 结构 | P40: =IF(COUNTIF($M$2:$M$51,M40)>1,"⚠ 重复","唯一") -> 唯一
...

Sheet 知识域容量
A1: 知识域 | B1: 前50篇出现次数 | C1: 说明
A2: 人体 | B2: =COUNTIF(前50篇台账!$J$2:$L$51,A2) -> 2 | C2: 组合层去重，单域可在不同三元组中复现
A3: 光学 | B3: =COUNTIF(前50篇台账!$J$2:$L$51,A3) -> 17 | C3: 组合层去重，单域可在不同三元组中复现
A4: 几何 | B4: =COUNTIF(前50篇台账!$J$2:$L$51,A4) -> 4 | C4: 组合层去重，单域可在不同三元组中复现
A5: 力学 | B5: =COUNTIF(前50篇台账!$J$2:$L$51,A5) -> 5 | C5: 组合层去重，单域可在不同三元组中复现
A6: 动物 | B6: =COUNTIF(前50篇台账!$J$2:$L$51,A6) -> 2 | C6: 组合层去重，单域可在不同三元组中复现
A7: 化学 | B7: =COUNTIF(前50篇台账!$J$2:$L$51,A7) -> 7 | C7: 组合层去重，单域可在不同三元组中复现
A8: 历史 | B8: =COUNTIF(前50篇台账!$J$2:$L$51,A8) -> 4 | C8: 组合层去重，单域可在不同三元组中复现
A9: 图书馆学 | B9: =COUNTIF(前50篇台账!$J$2:$L$51,A9) -> 1 | C9: 组合层去重，单域可在不同三元组中复现
A10: 地理 | B10: =COUNTIF(前50篇台账!$J$2:$L$51,A10) -> 4 | C10: 组合层去重，单域可在不同三元组中复现
A11: 地质 | B11: =COUNTIF(前50篇台账!$J$2:$L$51,A11) -> 1 | C11: 组合层去重，单域可在不同三元组中复现
A12: 声学 | B12: =COUNTIF(前50篇台账!$J$2:$L$51,A12) -> 10 | C12: 组合层去重，单域可在不同三元组中复现
A13: 天文 | B13: =COUNTIF(前50篇台账!$J$2:$L$51,A13) -> 2 | C13: 组合层去重，单域可在不同三元组中复现
... A36: 食品化学 | B36: =COUNTIF(前50篇台账!$J$2:$L$51,A36) -> 3 | C36: 组合层去重，单域可在不同三元组中复现
A37: 合计（应=150） | B37: =SUM(B2:B36) -> 150

Sheet 说明
A1: 《学堂奇事録》· 前50篇原理去重台账
A3: 用途：主编逐案登记，强制保证「三原理组合在 200 篇内不重复」。
A5: 列说明：
A6: · 三原理三元组（标准化）：三个核心原理按统一顺序排列后用 + 连接，是去重的唯一键。
A7: · 重复校验：=COUNTIF 自动比对全表；显示「唯一」即合格，「⚠ 重复」需改写谜题机制。
A8: · 知识域为「组合层」去重——单个域（如气象、光学）可在不同三元组中复现，三元组本身唯一即可。
A10: 新增第 51 篇及以后的流程：
A11: 1. 先确定该案的三个核心原理，按拼音/笔画统一排序写入「三原理三元组」列。
A12: 2. 向下复制「重复校验」公式，并把公式内的 $M$2:$M$51 范围扩展到新行。
A13: 3. 若显示「⚠ 重复」，更换其中至少一个核心原理或改换载体场景。
A15: 非重复的可行性证明：约 24 个知识域，三原理组合数 C(24,3)=2024 种；
A16: 即便只保留对小学生有意义、可日常化、可家庭复现的约 15%，也有约 300 种 > 200 篇所需。
A18: 基线：项目正典 V1.0（2026-06-04）。已剔除废弃角色「阿文」，其职能并入葛西全藏与陸珣。
